<?xml version='1.0'?>
<sdf version='1.7'>
    <model name='my_vehicle'>
        <link name='link_0'>
            <inertial>
                <mass>0.146363</mass>
                <inertia>
                    <ixx>0.00644802</ixx>
                    <ixy>0</ixy>
                    <ixz>0</ixz>
                    <iyy>0.0217131</iyy>
                    <iyz>0</iyz>
                    <izz>0.0275698</izz>
                </inertia>
                <pose>0 0 0.4 0 -0 0</pose>
            </inertial>
            <pose>0.150188 -0.001044 0.062375 0 -0 0</pose>
            <gravity>1</gravity>
            <self_collide>0</self_collide>
            <kinematic>0</kinematic>
            <enable_wind>0</enable_wind>
            <visual name='visual'>
                <pose>0 0 0 0 -0 0</pose>
                <geometry>
                    <box>
                        <size>1.32513 0.710223 0.155699</size>
                    </box>
                </geometry>
                <material>
                    <lighting>1</lighting>
                    <script>
                        <uri>file://media/materials/scripts/gazebo.material</uri>
                        <name>Gazebo/Grey</name>
                    </script>
                    <shader type='pixel'>
                        <normal_map>__default__</normal_map>
                    </shader>
                    <ambient>0.3 0.3 0.3 1</ambient>
                    <diffuse>0.7 0.7 0.7 1</diffuse>
                    <specular>0.01 0.01 0.01 1</specular>
                    <emissive>0 0 0 1</emissive>
                </material>
                <transparency>0</transparency>
                <cast_shadows>1</cast_shadows>
            </visual>
            <collision name='collision'>
                <laser_retro>0</laser_retro>
                <max_contacts>10</max_contacts>
                <pose>0 0 0 0 -0 0</pose>
                <geometry>
                    <box>
                        <size>1.32513 0.710223 0.155699</size>
                    </box>
                </geometry>
                <surface>
                    <friction>
                        <ode>
                            <mu>1</mu>
                            <mu2>1</mu2>
                            <fdir1>0 0 0</fdir1>
                            <slip1>0</slip1>
                            <slip2>0</slip2>
                        </ode>
                        <torsional>
                            <coefficient>1</coefficient>
                            <patch_radius>0</patch_radius>
                            <surface_radius>0</surface_radius>
                            <use_patch_radius>1</use_patch_radius>
                            <ode>
                                <slip>0</slip>
                            </ode>
                        </torsional>
                    </friction>
                    <bounce>
                        <restitution_coefficient>0</restitution_coefficient>
                        <threshold>1e+06</threshold>
                    </bounce>
                    <contact>
                        <collide_without_contact>0</collide_without_contact>
                        <collide_without_contact_bitmask>1</collide_without_contact_bitmask>
                        <collide_bitmask>1</collide_bitmask>
                        <ode>
                            <soft_cfm>0</soft_cfm>
                            <soft_erp>0.2</soft_erp>
                            <kp>1e+13</kp>
                            <kd>1</kd>
                            <max_vel>0.01</max_vel>
                            <min_depth>0</min_depth>
                        </ode>
                        <bullet>
                            <split_impulse>1</split_impulse>
                            <split_impulse_penetration_threshold>-0.01</split_impulse_penetration_threshold>
                            <soft_cfm>0</soft_cfm>
                            <soft_erp>0.2</soft_erp>
                            <kp>1e+13</kp>
                            <kd>1</kd>
                        </bullet>
                    </contact>
                </surface>
            </collision>
        </link>
        <link name='link_1'>
            <inertial>
                <mass>1</mass>
                <inertia>
                    <ixx>0.1</ixx>
                    <ixy>0</ixy>
                    <ixz>0</ixz>
                    <iyy>0.1</iyy>
                    <iyz>0</iyz>
                    <izz>0.1</izz>
                </inertia>
                <pose>0 0 0 0 -0 0</pose>
            </inertial>
            <pose>-0.212255 -0.484781 -0.037625 1.5707 -0 0</pose>
            <gravity>1</gravity>
            <self_collide>0</self_collide>
            <kinematic>0</kinematic>
            <enable_wind>0</enable_wind>
            <visual name='visual'>
                <pose>0 0 0 0 -0 0</pose>
                <geometry>
                    <cylinder>
                        <radius>0.3</radius>
                        <length>0.25</length>
                    </cylinder>
                </geometry>
                <material>
                    <lighting>1</lighting>
                    <script>
                        <uri>file://media/materials/scripts/gazebo.material</uri>
                        <name>Gazebo/Grey</name>
                    </script>
                    <shader type='pixel'>
                        <normal_map>__default__</normal_map>
                    </shader>
                    <ambient>0.3 0.3 0.3 1</ambient>
                    <diffuse>0.7 0.7 0.7 1</diffuse>
                    <specular>0.01 0.01 0.01 1</specular>
                    <emissive>0 0 0 1</emissive>
                </material>
                <transparency>0</transparency>
                <cast_shadows>1</cast_shadows>
            </visual>
            <collision name='collision'>
                <laser_retro>0</laser_retro>
                <max_contacts>10</max_contacts>
                <pose>0 0 0 0 -0 0</pose>
                <geometry>
                    <cylinder>
                        <radius>0.3</radius>
                        <length>0.25</length>
                    </cylinder>
                </geometry>
                <surface>
                    <friction>
                        <ode>
                            <mu>1</mu>
                            <mu2>1</mu2>
                            <fdir1>0 0 0</fdir1>
                            <slip1>0</slip1>
                            <slip2>0</slip2>
                        </ode>
                        <torsional>
                            <coefficient>1</coefficient>
                            <patch_radius>0</patch_radius>
                            <surface_radius>0</surface_radius>
                            <use_patch_radius>1</use_patch_radius>
                            <ode>
                                <slip>0</slip>
                            </ode>
                        </torsional>
                    </friction>
                    <bounce>
                        <restitution_coefficient>0</restitution_coefficient>
                        <threshold>1e+06</threshold>
                    </bounce>
                    <contact>
                        <collide_without_contact>0</collide_without_contact>
                        <collide_without_contact_bitmask>1</collide_without_contact_bitmask>
                        <collide_bitmask>1</collide_bitmask>
                        <ode>
                            <soft_cfm>0</soft_cfm>
                            <soft_erp>0.2</soft_erp>
                            <kp>1e+13</kp>
                            <kd>1</kd>
                            <max_vel>0.01</max_vel>
                            <min_depth>0</min_depth>
                        </ode>
                        <bullet>
                            <split_impulse>1</split_impulse>
                            <split_impulse_penetration_threshold>-0.01</split_impulse_penetration_threshold>
                            <soft_cfm>0</soft_cfm>
                            <soft_erp>0.2</soft_erp>
                            <kp>1e+13</kp>
                            <kd>1</kd>
                        </bullet>
                    </contact>
                </surface>
            </collision>
        </link>
        <link name='link_1_clone'>
            <inertial>
                <mass>1</mass>
                <inertia>
                    <ixx>0.1</ixx>
                    <ixy>0</ixy>
                    <ixz>0</ixz>
                    <iyy>0.1</iyy>
                    <iyz>0</iyz>
                    <izz>0.1</izz>
                </inertia>
                <pose>0 0 0 0 -0 0</pose>
            </inertial>
            <pose>-0.212255 0.475501 -0.037625 1.5707 -0 0</pose>
            <gravity>1</gravity>
            <self_collide>0</self_collide>
            <kinematic>0</kinematic>
            <enable_wind>0</enable_wind>
            <visual name='visual'>
                <pose>0 0 0 0 -0 0</pose>
                <geometry>
                    <cylinder>
                        <radius>0.3</radius>
                        <length>0.25</length>
                    </cylinder>
                </geometry>
                <material>
                    <lighting>1</lighting>
                    <script>
                        <uri>file://media/materials/scripts/gazebo.material</uri>
                        <name>Gazebo/Grey</name>
                    </script>
                    <shader type='pixel'>
                        <normal_map>__default__</normal_map>
                    </shader>
                    <ambient>0.3 0.3 0.3 1</ambient>
                    <diffuse>0.7 0.7 0.7 1</diffuse>
                    <specular>0.01 0.01 0.01 1</specular>
                    <emissive>0 0 0 1</emissive>
                </material>
                <transparency>0</transparency>
                <cast_shadows>1</cast_shadows>
            </visual>
            <collision name='collision'>
                <laser_retro>0</laser_retro>
                <max_contacts>10</max_contacts>
                <pose>0 0 0 0 -0 0</pose>
                <geometry>
                    <cylinder>
                        <radius>0.3</radius>
                        <length>0.25</length>
                    </cylinder>
                </geometry>
                <surface>
                    <friction>
                        <ode>
                            <mu>1</mu>
                            <mu2>1</mu2>
                            <fdir1>0 0 0</fdir1>
                            <slip1>0</slip1>
                            <slip2>0</slip2>
                        </ode>
                        <torsional>
                            <coefficient>1</coefficient>
                            <patch_radius>0</patch_radius>
                            <surface_radius>0</surface_radius>
                            <use_patch_radius>1</use_patch_radius>
                            <ode>
                                <slip>0</slip>
                            </ode>
                        </torsional>
                    </friction>
                    <bounce>
                        <restitution_coefficient>0</restitution_coefficient>
                        <threshold>1e+06</threshold>
                    </bounce>
                    <contact>
                        <collide_without_contact>0</collide_without_contact>
                        <collide_without_contact_bitmask>1</collide_without_contact_bitmask>
                        <collide_bitmask>1</collide_bitmask>
                        <ode>
                            <soft_cfm>0</soft_cfm>
                            <soft_erp>0.2</soft_erp>
                            <kp>1e+13</kp>
                            <kd>1</kd>
                            <max_vel>0.01</max_vel>
                            <min_depth>0</min_depth>
                        </ode>
                        <bullet>
                            <split_impulse>1</split_impulse>
                            <split_impulse_penetration_threshold>-0.01</split_impulse_penetration_threshold>
                            <soft_cfm>0</soft_cfm>
                            <soft_erp>0.2</soft_erp>
                            <kp>1e+13</kp>
                            <kd>1</kd>
                        </bullet>
                    </contact>
                </surface>
            </collision>
        </link>
        <link name='link_2'>
            <inertial>
                <mass>0.514234</mass>
                <inertia>
                    <ixx>0.0330073</ixx>
                    <ixy>0</ixy>
                    <ixz>0</ixz>
                    <iyy>0.0330073</iyy>
                    <iyz>0</iyz>
                    <izz>0.0330073</izz>
                </inertia>
                <pose>0 0 0 0 -0 0</pose>
            </inertial>
            <pose>0.612875 -0.00464 -0.137625 0 -0 0</pose>
            <gravity>1</gravity>
            <self_collide>0</self_collide>
            <kinematic>0</kinematic>
            <enable_wind>0</enable_wind>
            <visual name='visual'>
                <pose>0 0 0 0 -0 0</pose>
                <geometry>
                    <sphere>
                        <radius>0.2</radius>
                    </sphere>
                </geometry>
                <material>
                    <lighting>1</lighting>
                    <script>
                        <uri>file://media/materials/scripts/gazebo.material</uri>
                        <name>Gazebo/Grey</name>
                    </script>
                    <shader type='pixel'>
                        <normal_map>__default__</normal_map>
                    </shader>
                    <ambient>0.3 0.3 0.3 1</ambient>
                    <diffuse>0.7 0.7 0.7 1</diffuse>
                    <specular>0.01 0.01 0.01 1</specular>
                    <emissive>0 0 0 1</emissive>
                </material>
                <transparency>0</transparency>
                <cast_shadows>1</cast_shadows>
            </visual>
            <collision name='collision'>
                <laser_retro>0</laser_retro>
                <max_contacts>10</max_contacts>
                <pose>0 0 0 0 -0 0</pose>
                <geometry>
                    <sphere>
                        <radius>0.2</radius>
                    </sphere>
                </geometry>
                <surface>
                    <friction>
                        <ode>
                            <mu>1</mu>
                            <mu2>1</mu2>
                            <fdir1>0 0 0</fdir1>
                            <slip1>0</slip1>
                            <slip2>0</slip2>
                        </ode>
                        <torsional>
                            <coefficient>1</coefficient>
                            <patch_radius>0</patch_radius>
                            <surface_radius>0</surface_radius>
                            <use_patch_radius>1</use_patch_radius>
                            <ode>
                                <slip>0</slip>
                            </ode>
                        </torsional>
                    </friction>
                    <bounce>
                        <restitution_coefficient>0</restitution_coefficient>
                        <threshold>1e+06</threshold>
                    </bounce>
                    <contact>
                        <collide_without_contact>0</collide_without_contact>
                        <collide_without_contact_bitmask>1</collide_without_contact_bitmask>
                        <collide_bitmask>1</collide_bitmask>
                        <ode>
                            <soft_cfm>0</soft_cfm>
                            <soft_erp>0.2</soft_erp>
                            <kp>1e+13</kp>
                            <kd>1</kd>
                            <max_vel>0.01</max_vel>
                            <min_depth>0</min_depth>
                        </ode>
                        <bullet>
                            <split_impulse>1</split_impulse>
                            <split_impulse_penetration_threshold>-0.01</split_impulse_penetration_threshold>
                            <soft_cfm>0</soft_cfm>
                            <soft_erp>0.2</soft_erp>
                            <kp>1e+13</kp>
                            <kd>1</kd>
                        </bullet>
                    </contact>
                </surface>
            </collision>
        </link>
        <model name='depth_camera'>
            <link name='link'>
                <pose>0 0 0.05 0 -0 0</pose>
                <inertial>
                    <mass>0.1</mass>
                    <inertia>
                        <ixx>0.000166667</ixx>
                        <iyy>0.000166667</iyy>
                        <izz>0.000166667</izz>
                        <ixy>0</ixy>
                        <ixz>0</ixz>
                        <iyz>0</iyz>
                    </inertia>
                    <pose>0 0 0 0 -0 0</pose>
                </inertial>
                <collision name='collision'>
                    <geometry>
                        <box>
                            <size>0.1 0.1 0.1</size>
                        </box>
                    </geometry>
                    <max_contacts>10</max_contacts>
                    <surface>
                        <contact>
                            <ode/>
                        </contact>
                        <bounce/>
                        <friction>
                            <torsional>
                                <ode/>
                            </torsional>
                            <ode/>
                        </friction>
                    </surface>
                </collision>
                <visual name='visual'>
                    <geometry>
                        <box>
                            <size>0.1 0.1 0.1</size>
                        </box>
                    </geometry>
                </visual>
                <sensor name='camera' type='depth'>
                    <camera>
                        <horizontal_fov>1.047</horizontal_fov>
                        <image>
                            <width>320</width>
                            <height>240</height>
                        </image>
                        <clip>
                            <near>0.1</near>
                            <far>100</far>
                        </clip>
                    </camera>
                    <plugin name="camera_plugin" filename="libgazebo_ros_openni_kinect.so">
                        <baseline>0.2</baseline>
                        <alwaysOn>true</alwaysOn>
                        <!-- Keep this zero, update_rate in the parent <sensor> tag
       will control the frame rate. -->
                        <updateRate>20</updateRate>
                        <cameraName>camera_ir</cameraName>
                        <imageTopicName>/camera/color/image_raw</imageTopicName>
                        <cameraInfoTopicName>/camera/color/camera_info</cameraInfoTopicName>
                        <depthImageTopicName>/camera/depth/image_raw</depthImageTopicName>
                        <depthImageCameraInfoTopicName>/camera/depth/camera_info</depthImageCameraInfoTopicName>
                        <pointCloudTopicName>/camera/depth/points</pointCloudTopicName>
                        <frameName>depth_camera_link</frameName>
                        <pointCloudCutoff>0.05</pointCloudCutoff>
                        <distortionK1>0</distortionK1>
                        <distortionK2>0</distortionK2>
                        <distortionK3>0</distortionK3>
                        <distortionT1>0</distortionT1>
                        <distortionT2>0</distortionT2>
                        <CxPrime>0</CxPrime>
                        <Cx>0</Cx>
                        <Cy>0</Cy>
                        <focalLength>0</focalLength>
                        <hackBaseline>0</hackBaseline>
                    </plugin>
                    <always_on>1</always_on>
                    <update_rate>20</update_rate>
                    <visualize>1</visualize>
                </sensor>
                <self_collide>0</self_collide>
                <enable_wind>0</enable_wind>
                <kinematic>0</kinematic>
            </link>
            <pose>-0.338553 0.014965 0.150501 0 -0 0</pose>
        </model>
        <joint name='link_0_JOINT_0' type='revolute'>
            <parent>link_0</parent>
            <child>link_1_clone</child>
            <pose>0 0 -0.03 0 -0 0</pose>
            <axis>
                <xyz>0 0 1</xyz>
                <limit>
                    <lower>-1.79769e+308</lower>
                    <upper>1.79769e+308</upper>
                    <effort>-1</effort>
                    <velocity>-1</velocity>
                </limit>
                <dynamics>
                    <spring_reference>0</spring_reference>
                    <spring_stiffness>0</spring_stiffness>
                    <damping>0</damping>
                    <friction>0</friction>
                </dynamics>
            </axis>
            <physics>
                <ode>
                    <limit>
                        <cfm>0</cfm>
                        <erp>0.2</erp>
                    </limit>
                    <suspension>
                        <cfm>0</cfm>
                        <erp>0.2</erp>
                    </suspension>
                </ode>
            </physics>
        </joint>
        <joint name='link_0_JOINT_2' type='revolute'>
            <parent>link_0</parent>
            <child>link_1</child>
            <pose>0 0 0 0 -0 0</pose>
            <axis>
                <xyz>1 0 0</xyz>
                <limit>
                    <lower>-1.79769e+308</lower>
                    <upper>1.79769e+308</upper>
                    <effort>-1</effort>
                    <velocity>-1</velocity>
                </limit>
                <dynamics>
                    <spring_reference>0</spring_reference>
                    <spring_stiffness>0</spring_stiffness>
                    <damping>0</damping>
                    <friction>0</friction>
                </dynamics>
            </axis>
            <physics>
                <ode>
                    <limit>
                        <cfm>0</cfm>
                        <erp>0.2</erp>
                    </limit>
                    <suspension>
                        <cfm>0</cfm>
                        <erp>0.2</erp>
                    </suspension>
                </ode>
            </physics>
        </joint>
        <joint name='link_0_JOINT_3' type='ball'>
            <parent>link_0</parent>
            <child>link_2</child>
            <pose>0 0 0 0 -0 0</pose>
            <physics>
                <ode>
                    <limit>
                        <cfm>0</cfm>
                        <erp>0.2</erp>
                    </limit>
                    <suspension>
                        <cfm>0</cfm>
                        <erp>0.2</erp>
                    </suspension>
                </ode>
            </physics>
        </joint>
        <joint name='link_0_JOINT_4' type='fixed'>
            <parent>link_0</parent>
            <child>depth_camera::link</child>
            <pose>0 0 0 0 -0 0</pose>
            <physics>
                <ode>
                    <limit>
                        <cfm>0</cfm>
                        <erp>0.2</erp>
                    </limit>
                    <suspension>
                        <cfm>0</cfm>
                        <erp>0.2</erp>
                    </suspension>
                </ode>
            </physics>
        </joint>
        <static>0</static>
        <allow_auto_disable>1</allow_auto_disable>
        <plugin name='follower' filename='libFollowerPlugin.so'/>
    </model>
</sdf>